Traceback (most recent call last):
  File "<string>", line 1, in <module>
  File "main.py", line 39, in <module>
    main()
  File "main.py", line 27, in main
    damageCal.restoreFatigueLifeSamples(maxLoads=20)
  File "/home/blueman69/git/ProbabilisticFatigue/src/combinedModel.py", line 83, in restoreFatigueLifeSamples
    self.transformGPs()
  File "/home/blueman69/git/ProbabilisticFatigue/src/combinedModel.py", line 198, in transformGPs
    self.slicedTotal = sliceArrsvmap(self.SNew, self.amplitudes)
  File "/home/blueman69/anaconda3/envs/dataSc/lib/python3.9/site-packages/jax/_src/traceback_util.py", line 162, in reraise_with_filtered_traceback
    return fun(*args, **kwargs)
  File "/home/blueman69/anaconda3/envs/dataSc/lib/python3.9/site-packages/jax/_src/api.py", line 473, in cache_miss
    out_flat = xla.xla_call(
  File "/home/blueman69/anaconda3/envs/dataSc/lib/python3.9/site-packages/jax/core.py", line 1765, in bind
    return call_bind(self, fun, *args, **params)
  File "/home/blueman69/anaconda3/envs/dataSc/lib/python3.9/site-packages/jax/core.py", line 1781, in call_bind
    outs = top_trace.process_call(primitive, fun_, tracers, params)
  File "/home/blueman69/anaconda3/envs/dataSc/lib/python3.9/site-packages/jax/core.py", line 678, in process_call
    return primitive.impl(f, *tracers, **params)
  File "/home/blueman69/anaconda3/envs/dataSc/lib/python3.9/site-packages/jax/_src/dispatch.py", line 185, in _xla_call_impl
    return compiled_fun(*args)
  File "/home/blueman69/anaconda3/envs/dataSc/lib/python3.9/site-packages/jax/_src/dispatch.py", line 615, in _execute_compiled
    out_bufs_flat = compiled.execute(input_bufs_flat)
jax._src.traceback_util.UnfilteredStackTrace: jaxlib.xla_extension.XlaRuntimeError: RESOURCE_EXHAUSTED: Out of memory allocating 640000000000 bytes.

The stack trace below excludes JAX-internal frames.
The preceding is the original exception that occurred, unmodified.

--------------------

The above exception was the direct cause of the following exception:

Traceback (most recent call last):
  File "/home/blueman69/anaconda3/envs/dataSc/lib/python3.9/site-packages/pudb/__init__.py", line 148, in runscript
    dbg._runscript(mainpyfile)
  File "/home/blueman69/anaconda3/envs/dataSc/lib/python3.9/site-packages/pudb/debugger.py", line 514, in _runscript
    self.run(statement)
  File "/home/blueman69/anaconda3/envs/dataSc/lib/python3.9/bdb.py", line 580, in run
    exec(cmd, globals, locals)
  File "<string>", line 1, in <module>
  File "main.py", line 39, in <module>
    main()
  File "main.py", line 27, in main
    damageCal.restoreFatigueLifeSamples(maxLoads=20)
  File "/home/blueman69/git/ProbabilisticFatigue/src/combinedModel.py", line 83, in restoreFatigueLifeSamples
    self.transformGPs()
  File "/home/blueman69/git/ProbabilisticFatigue/src/combinedModel.py", line 198, in transformGPs
    self.slicedTotal = sliceArrsvmap(self.SNew, self.amplitudes)
jaxlib.xla_extension.XlaRuntimeError: RESOURCE_EXHAUSTED: Out of memory allocating 640000000000 bytes.
