Traceback (most recent call last):
  File "/home/blueman69/anaconda3/envs/dataSc/lib/python3.9/site-packages/jax/_src/lax/lax.py", line 120, in broadcast_shapes
    return _broadcast_shapes_cached(*shapes)
  File "/home/blueman69/anaconda3/envs/dataSc/lib/python3.9/site-packages/jax/_src/util.py", line 219, in wrapper
    return cached(config._trace_context(), *args, **kwargs)
  File "/home/blueman69/anaconda3/envs/dataSc/lib/python3.9/site-packages/jax/_src/util.py", line 212, in cached
    return f(*args, **kwargs)
  File "/home/blueman69/anaconda3/envs/dataSc/lib/python3.9/site-packages/jax/_src/lax/lax.py", line 126, in _broadcast_shapes_cached
    return _broadcast_shapes_uncached(*shapes)
  File "/home/blueman69/anaconda3/envs/dataSc/lib/python3.9/site-packages/jax/_src/lax/lax.py", line 142, in _broadcast_shapes_uncached
    raise ValueError("Incompatible shapes for broadcasting: {}"
ValueError: Incompatible shapes for broadcasting: ((1, 180), (180, 8000), (1, 1))

During handling of the above exception, another exception occurred:

Traceback (most recent call last):
  File "<string>", line 1, in <module>
  File "main.py", line 39, in <module>
    main()
  File "main.py", line 27, in main
    damageCal.restoreFatigueLifeSamples(maxLoads=20)
  File "/home/blueman69/git/ProbabilisticFatigue/src/combinedModel.py", line 84, in restoreFatigueLifeSamples
    self.transformGPs()
  File "/home/blueman69/git/ProbabilisticFatigue/src/combinedModel.py", line 196, in transformGPs
    self.slicedTotal = sliceArrsvmap(self.SNew, self.amplitudes, self.totalN)
  File "/home/blueman69/anaconda3/envs/dataSc/lib/python3.9/site-packages/jax/_src/traceback_util.py", line 162, in reraise_with_filtered_traceback
    return fun(*args, **kwargs)
  File "/home/blueman69/anaconda3/envs/dataSc/lib/python3.9/site-packages/jax/_src/api.py", line 1485, in vmap_f
    out_flat = batching.batch(
  File "/home/blueman69/anaconda3/envs/dataSc/lib/python3.9/site-packages/jax/linear_util.py", line 168, in call_wrapped
    ans = self.f(*args, **dict(self.params, **kwargs))
  File "/home/blueman69/git/ProbabilisticFatigue/src/combinedModel.py", line 39, in sliceArrs
    return jnp.where(mask, jnp.transpose(out), -10)
  File "/home/blueman69/anaconda3/envs/dataSc/lib/python3.9/site-packages/jax/_src/numpy/lax_numpy.py", line 989, in where
    return _where(condition, x, y)
  File "/home/blueman69/anaconda3/envs/dataSc/lib/python3.9/site-packages/jax/_src/traceback_util.py", line 162, in reraise_with_filtered_traceback
    return fun(*args, **kwargs)
  File "/home/blueman69/anaconda3/envs/dataSc/lib/python3.9/site-packages/jax/_src/api.py", line 473, in cache_miss
    out_flat = xla.xla_call(
  File "/home/blueman69/anaconda3/envs/dataSc/lib/python3.9/site-packages/jax/core.py", line 1765, in bind
    return call_bind(self, fun, *args, **params)
  File "/home/blueman69/anaconda3/envs/dataSc/lib/python3.9/site-packages/jax/core.py", line 1781, in call_bind
    outs = top_trace.process_call(primitive, fun_, tracers, params)
  File "/home/blueman69/anaconda3/envs/dataSc/lib/python3.9/site-packages/jax/interpreters/batching.py", line 226, in process_call
    vals_out = call_primitive.bind(f_, *vals, **params)
  File "/home/blueman69/anaconda3/envs/dataSc/lib/python3.9/site-packages/jax/core.py", line 1765, in bind
    return call_bind(self, fun, *args, **params)
  File "/home/blueman69/anaconda3/envs/dataSc/lib/python3.9/site-packages/jax/core.py", line 1781, in call_bind
    outs = top_trace.process_call(primitive, fun_, tracers, params)
  File "/home/blueman69/anaconda3/envs/dataSc/lib/python3.9/site-packages/jax/core.py", line 678, in process_call
    return primitive.impl(f, *tracers, **params)
  File "/home/blueman69/anaconda3/envs/dataSc/lib/python3.9/site-packages/jax/_src/dispatch.py", line 182, in _xla_call_impl
    compiled_fun = _xla_callable(fun, device, backend, name, donated_invars,
  File "/home/blueman69/anaconda3/envs/dataSc/lib/python3.9/site-packages/jax/linear_util.py", line 285, in memoized_fun
    ans = call(fun, *args)
  File "/home/blueman69/anaconda3/envs/dataSc/lib/python3.9/site-packages/jax/_src/dispatch.py", line 230, in _xla_callable_uncached
    return lower_xla_callable(fun, device, backend, name, donated_invars, False,
  File "/home/blueman69/anaconda3/envs/dataSc/lib/python3.9/site-packages/jax/_src/profiler.py", line 206, in wrapper
    return func(*args, **kwargs)
  File "/home/blueman69/anaconda3/envs/dataSc/lib/python3.9/site-packages/jax/_src/dispatch.py", line 272, in lower_xla_callable
    jaxpr, out_avals, consts = pe.trace_to_jaxpr_final(
  File "/home/blueman69/anaconda3/envs/dataSc/lib/python3.9/site-packages/jax/_src/profiler.py", line 206, in wrapper
    return func(*args, **kwargs)
  File "/home/blueman69/anaconda3/envs/dataSc/lib/python3.9/site-packages/jax/interpreters/partial_eval.py", line 1893, in trace_to_jaxpr_final
    jaxpr, out_avals, consts = trace_to_subjaxpr_dynamic(
  File "/home/blueman69/anaconda3/envs/dataSc/lib/python3.9/site-packages/jax/interpreters/partial_eval.py", line 1865, in trace_to_subjaxpr_dynamic
    ans = fun.call_wrapped(*in_tracers_)
  File "/home/blueman69/anaconda3/envs/dataSc/lib/python3.9/site-packages/jax/linear_util.py", line 168, in call_wrapped
    ans = self.f(*args, **dict(self.params, **kwargs))
  File "/home/blueman69/anaconda3/envs/dataSc/lib/python3.9/site-packages/jax/_src/numpy/util.py", line 380, in _where
    condition, x, y = _broadcast_arrays(condition, x, y)
  File "/home/blueman69/anaconda3/envs/dataSc/lib/python3.9/site-packages/jax/_src/traceback_util.py", line 162, in reraise_with_filtered_traceback
    return fun(*args, **kwargs)
  File "/home/blueman69/anaconda3/envs/dataSc/lib/python3.9/site-packages/jax/_src/api.py", line 473, in cache_miss
    out_flat = xla.xla_call(
  File "/home/blueman69/anaconda3/envs/dataSc/lib/python3.9/site-packages/jax/core.py", line 1765, in bind
    return call_bind(self, fun, *args, **params)
  File "/home/blueman69/anaconda3/envs/dataSc/lib/python3.9/site-packages/jax/core.py", line 1781, in call_bind
    outs = top_trace.process_call(primitive, fun_, tracers, params)
  File "/home/blueman69/anaconda3/envs/dataSc/lib/python3.9/site-packages/jax/interpreters/batching.py", line 226, in process_call
    vals_out = call_primitive.bind(f_, *vals, **params)
  File "/home/blueman69/anaconda3/envs/dataSc/lib/python3.9/site-packages/jax/core.py", line 1765, in bind
    return call_bind(self, fun, *args, **params)
  File "/home/blueman69/anaconda3/envs/dataSc/lib/python3.9/site-packages/jax/core.py", line 1781, in call_bind
    outs = top_trace.process_call(primitive, fun_, tracers, params)
  File "/home/blueman69/anaconda3/envs/dataSc/lib/python3.9/site-packages/jax/interpreters/partial_eval.py", line 1583, in process_call
    jaxpr, out_avals, consts = trace_to_subjaxpr_dynamic(
  File "/home/blueman69/anaconda3/envs/dataSc/lib/python3.9/site-packages/jax/interpreters/partial_eval.py", line 1865, in trace_to_subjaxpr_dynamic
    ans = fun.call_wrapped(*in_tracers_)
  File "/home/blueman69/anaconda3/envs/dataSc/lib/python3.9/site-packages/jax/linear_util.py", line 168, in call_wrapped
    ans = self.f(*args, **dict(self.params, **kwargs))
  File "/home/blueman69/anaconda3/envs/dataSc/lib/python3.9/site-packages/jax/_src/numpy/util.py", line 338, in _broadcast_arrays
    result_shape = lax.broadcast_shapes(*shapes)
  File "/home/blueman69/anaconda3/envs/dataSc/lib/python3.9/site-packages/jax/_src/lax/lax.py", line 122, in broadcast_shapes
    return _broadcast_shapes_uncached(*shapes)
  File "/home/blueman69/anaconda3/envs/dataSc/lib/python3.9/site-packages/jax/_src/lax/lax.py", line 142, in _broadcast_shapes_uncached
    raise ValueError("Incompatible shapes for broadcasting: {}"
jax._src.traceback_util.UnfilteredStackTrace: ValueError: Incompatible shapes for broadcasting: ((1, 180), (180, 8000), (1, 1))

The stack trace below excludes JAX-internal frames.
The preceding is the original exception that occurred, unmodified.

--------------------

The above exception was the direct cause of the following exception:

Traceback (most recent call last):
  File "/home/blueman69/anaconda3/envs/dataSc/lib/python3.9/site-packages/pudb/__init__.py", line 148, in runscript
    dbg._runscript(mainpyfile)
  File "/home/blueman69/anaconda3/envs/dataSc/lib/python3.9/site-packages/pudb/debugger.py", line 514, in _runscript
    self.run(statement)
  File "/home/blueman69/anaconda3/envs/dataSc/lib/python3.9/bdb.py", line 580, in run
    exec(cmd, globals, locals)
  File "<string>", line 1, in <module>
  File "main.py", line 39, in <module>
    main()
  File "main.py", line 27, in main
    damageCal.restoreFatigueLifeSamples(maxLoads=20)
  File "/home/blueman69/git/ProbabilisticFatigue/src/combinedModel.py", line 84, in restoreFatigueLifeSamples
    self.transformGPs()
  File "/home/blueman69/git/ProbabilisticFatigue/src/combinedModel.py", line 196, in transformGPs
    self.slicedTotal = sliceArrsvmap(self.SNew, self.amplitudes, self.totalN)
  File "/home/blueman69/git/ProbabilisticFatigue/src/combinedModel.py", line 39, in sliceArrs
    return jnp.where(mask, jnp.transpose(out), -10)
  File "/home/blueman69/anaconda3/envs/dataSc/lib/python3.9/site-packages/jax/_src/numpy/lax_numpy.py", line 989, in where
    return _where(condition, x, y)
  File "/home/blueman69/anaconda3/envs/dataSc/lib/python3.9/site-packages/jax/_src/numpy/util.py", line 380, in _where
    condition, x, y = _broadcast_arrays(condition, x, y)
  File "/home/blueman69/anaconda3/envs/dataSc/lib/python3.9/site-packages/jax/_src/numpy/util.py", line 338, in _broadcast_arrays
    result_shape = lax.broadcast_shapes(*shapes)
ValueError: Incompatible shapes for broadcasting: ((1, 180), (180, 8000), (1, 1))
