Traceback (most recent call last):
  File "/home/blueman69/anaconda3/envs/dataSc/lib/python3.9/site-packages/jax/_src/api.py", line 1503, in _get_axis_size
    return shape[axis]
IndexError: tuple index out of range

The above exception was the direct cause of the following exception:

Traceback (most recent call last):
  File "<string>", line 1, in <module>
  File "main.py", line 40, in <module>
    main()
  File "main.py", line 28, in main
    damageCal.restoreFatigueLifeSamples(maxLoads=20)
  File "/home/blueman69/git/ProbabilisticFatigue/src/combinedModel.py", line 175, in restoreFatigueLifeSamples
    self.sampleFatigueLife(maxLoads=maxLoads)
  File "/home/blueman69/git/ProbabilisticFatigue/src/combinedModel.py", line 133, in sampleFatigueLife
    self.joinAmplitudesStress(maxLoads)
  File "/home/blueman69/git/ProbabilisticFatigue/src/combinedModel.py", line 110, in joinAmplitudesStress
    self.cycles, self.amplitudes = vHisto(loads)
  File "/home/blueman69/anaconda3/envs/dataSc/lib/python3.9/site-packages/jax/_src/traceback_util.py", line 162, in reraise_with_filtered_traceback
    return fun(*args, **kwargs)
  File "/home/blueman69/anaconda3/envs/dataSc/lib/python3.9/site-packages/jax/_src/api.py", line 1483, in vmap_f
    _mapped_axis_size(in_tree, args_flat, in_axes_flat, "vmap",
  File "/home/blueman69/anaconda3/envs/dataSc/lib/python3.9/site-packages/jax/_src/api.py", line 1510, in _mapped_axis_size
    mapped_axis_sizes = {_get_axis_size(name, np.shape(x), d)
  File "/home/blueman69/anaconda3/envs/dataSc/lib/python3.9/site-packages/jax/_src/api.py", line 1510, in <setcomp>
    mapped_axis_sizes = {_get_axis_size(name, np.shape(x), d)
  File "/home/blueman69/anaconda3/envs/dataSc/lib/python3.9/site-packages/jax/_src/api.py", line 1506, in _get_axis_size
    raise ValueError(f"{name} was requested to map its argument along axis {axis}, "
jax._src.traceback_util.UnfilteredStackTrace: ValueError: vmap was requested to map its argument along axis 1, which implies that its rank should be at least 2, but is only 1 (its shape is (20000,))

The stack trace below excludes JAX-internal frames.
The preceding is the original exception that occurred, unmodified.

--------------------

The above exception was the direct cause of the following exception:

Traceback (most recent call last):
  File "/home/blueman69/anaconda3/envs/dataSc/lib/python3.9/site-packages/pudb/__init__.py", line 148, in runscript
    dbg._runscript(mainpyfile)
  File "/home/blueman69/anaconda3/envs/dataSc/lib/python3.9/site-packages/pudb/debugger.py", line 514, in _runscript
    self.run(statement)
  File "/home/blueman69/anaconda3/envs/dataSc/lib/python3.9/bdb.py", line 580, in run
    exec(cmd, globals, locals)
  File "<string>", line 1, in <module>
  File "main.py", line 40, in <module>
    main()
  File "main.py", line 28, in main
    damageCal.restoreFatigueLifeSamples(maxLoads=20)
  File "/home/blueman69/git/ProbabilisticFatigue/src/combinedModel.py", line 175, in restoreFatigueLifeSamples
    self.sampleFatigueLife(maxLoads=maxLoads)
  File "/home/blueman69/git/ProbabilisticFatigue/src/combinedModel.py", line 133, in sampleFatigueLife
    self.joinAmplitudesStress(maxLoads)
  File "/home/blueman69/git/ProbabilisticFatigue/src/combinedModel.py", line 110, in joinAmplitudesStress
    self.cycles, self.amplitudes = vHisto(loads)
ValueError: vmap was requested to map its argument along axis 1, which implies that its rank should be at least 2, but is only 1 (its shape is (20000,))
